<?xml version="1.0" encoding="utf-8"?>

<robot name="Wheel-Legged-Infantry">
    <mujoco>
        <compiler meshdir="../meshes/" balanceinertia="false" discardvisual="false" fusestatic="false"/>
    </mujoco>
    <link name="base_link">
        <inertial>
            <origin xyz="0.0066 0 -0.0318" rpy="0 0 0"/>
            <mass value="11.513"/>
            <inertia ixx="0.1392" ixy="0.001321" ixz="-0.01715" iyy="0.2492" iyz="0.0002667" izz="0.3111"/>
        </inertial>
        <visual>
            <origin xyz="0 0 0" rpy="0 0 0"/>
            <geometry>
                <mesh filename="../meshes/base.STL"/>
            </geometry>
            <material name="">
                <color rgba="0.1 0.1 0.1 1"/>
            </material>
        </visual>
        <collision>
            <origin xyz="0 0 -0.03" rpy="0 0 0"/>
            <geometry>
                <box size="0.5 0.20 0.2"/>
            </geometry>
        </collision>
        <collision>
            <origin xyz="0 0 -0.04" rpy="0 0 0"/>
            <geometry>
                <box size="0.25 0.32 0.12"/>
            </geometry>
        </collision>
        <collision>
            <origin xyz="0.257 0 -0.115" rpy="1.57079632 0 0"/>
            <geometry>
                <cylinder length="0.28" radius="0.02"/>
            </geometry>
        </collision>
        <collision>
            <origin xyz="-0.257 0 -0.115" rpy="1.57079632 0 0"/>
            <geometry>
                <cylinder length="0.28" radius="0.02"/>
            </geometry>
        </collision>
        <collision>
            <origin xyz="0.03 0 -0.148" rpy="1.57079632 0 0"/>
            <geometry>
                <cylinder length="0.22" radius="0.015"/>
            </geometry>
        </collision>
        <collision>
            <origin xyz="-0.03 0 -0.148" rpy="1.57079632 0 0"/>
            <geometry>
                <cylinder length="0.22" radius="0.015"/>
            </geometry>
        </collision>
    </link>
    <link name="hip_l_link">
        <inertial>
            <origin xyz="0.098 0 0" rpy="0 0 0"/>
            <mass value="0.934"/>
            <inertia ixx="0.0002846" ixy="0.0000143136" ixz="0.0001012944" iyy="0.003525624" iyz="-0.0000042544" izz="0.0032762672"/>
        </inertial>
        <visual>
            <origin xyz="0 0 0" rpy="0 0 0"/>
            <geometry>
                <mesh filename="../meshes/hip_link_l.STL"/>
            </geometry>
            <material name="">
                <color rgba="0.2 0.2 0.2 1"/>
            </material>
        </visual>
        <collision>
            <origin xyz="0.105 0 0" rpy="0 0 0"/>
            <geometry>
                <box size="0.21 0.015 0.06"/>
            </geometry>
        </collision>
        <collision>
            <origin xyz="0.210 0 0" rpy="1.57079632 0 0"/>
            <geometry>
                <cylinder length="0.015" radius="0.03"/>
            </geometry> 
        </collision>
    </link>
    <joint name="hip_l_joint" type="continuous">
        <origin xyz="0 0.179 0" rpy="0 1.5708 0"/>
        <parent link="base_link"/>
        <child link="hip_l_link"/>
        <axis xyz="0 1 0"/>
        <limit effort="80" velocity="20"/>
    </joint>
    <link name="knee_l_link">
        <inertial>
            <origin xyz="0.123 0 0" rpy="0 0 0"/>
            <mass value="0.67"/>
            <inertia ixx="0.0009460464" ixy="0.0016010944" ixz="0.000006592" iyy="0.0033157904" iyz="-0.0000033216" izz="0.0042459008"/>
        </inertial>
        <visual>
            <origin xyz="0 0 0" rpy="0 0 0"/>
            <geometry>
                <mesh filename="../meshes/knee_link_l.STL"/>
            </geometry>
            <material name="">
                <color rgba="0.3 0.3 0.3 1"/>
            </material>
        </visual>
        <collision>
            <origin xyz="0.124 0 0" rpy="0 0 0"/>
            <geometry>
                <box size="0.248 0.015 0.06"/>
            </geometry>
        </collision>
        <collision>
            <origin xyz="0 0 0" rpy="1.57079632 0 0"/>
            <geometry>
                <cylinder length="0.018" radius="0.03"/>
            </geometry> 
        </collision>
    </link>
    <joint name="knee_l_joint" type="revolute">
        <origin xyz="0.210 0.0165 0" rpy="0 3.1416 0"/>
        <parent link="hip_l_link"/>
        <child link="knee_l_link"/>
        <axis xyz="0 1 0"/>
        <limit lower="0.416" upper="2.153" effort="80" velocity="20"/>
    </joint>
    <link name="wheel_l">
        <inertial>
            <origin xyz="0 0 0" rpy="0 0 0"/>
            <mass value="0.468"/>
            <inertia ixx="0.00034258" ixy="0.0" ixz="0.0" iyy="0.00001" iyz="0.0" izz="0.000343769"/>
        </inertial>
        <visual>
            <origin xyz="0 0 0" rpy="0 0 0"/>
            <geometry>
                <mesh filename="../meshes/wheel_l.STL"/>
            </geometry>
            <material name="">
                <color rgba="0.05 0.05 0.05 1"/>
            </material>
        </visual>
        <collision>
            <origin xyz="0 0 0" rpy="1.57079632 0 0"/>
            <geometry>
                <cylinder length="0.015" radius="0.06"/>
            </geometry>
        </collision>
    </link>
    <joint name="wheel_l_joint" type="continuous">
        <origin xyz="0.248 0.0295 0" rpy="0 0 0"/>
        <parent link="knee_l_link"/>
        <child link="wheel_l"/>
        <axis xyz="0 1 0"/>
        <limit effort="5" velocity="60"/>
    </joint>
    <link name="hip_r_link">
        <inertial>
            <origin xyz="0.098 0 0" rpy="0 0 0"/>
            <mass value="0.934"/>
            <inertia ixx="0.0002846" ixy="0.0000143136" ixz="0.0001012944" iyy="0.003525624" iyz="-0.0000042544" izz="0.0032762672"/>
        </inertial>
        <visual>
            <origin xyz="0 0 0" rpy="0 0 0"/>
            <geometry>
                <mesh filename="../meshes/hip_link_r.STL"/>
            </geometry>
            <material name="">
                <color rgba="0.2 0.2 0.2 1"/>
            </material>
        </visual>
        <collision>
            <origin xyz="0.105 0 0" rpy="0 0 0"/>
            <geometry>
                <box size="0.21 0.015 0.06"/>
            </geometry>
        </collision>
        <collision>
            <origin xyz="0.210 0 0" rpy="1.57079632 0 0"/>
            <geometry>
                <cylinder length="0.015" radius="0.03"/>
            </geometry> 
        </collision>
    </link>
    <joint name="hip_r_joint" type="continuous">
        <origin xyz="0 -0.179 0" rpy="0 1.5708 0"/>
        <parent link="base_link"/>
        <child link="hip_r_link"/>
        <axis xyz="0 1 0"/>
        <limit effort="80" velocity="20"/>
    </joint>
    <link name="knee_r_link">
        <inertial>
            <origin xyz="0.123 0 0" rpy="0 0 0"/>
            <mass value="0.67"/>
            <inertia ixx="0.0009460464" ixy="0.0016010944" ixz="0.000006592" iyy="0.0033157904" iyz="-0.0000033216" izz="0.0042459008"/>
        </inertial>
        <visual>
            <origin xyz="0 0 0" rpy="0 0 0"/>
            <geometry>
                <mesh filename="../meshes/knee_link_r.STL"/>
            </geometry>
            <material name="">
                <color rgba="0.3 0.3 0.3 1"/>
            </material>
        </visual>
        <collision>
            <origin xyz="0.124 0 0" rpy="0 0 0"/>
            <geometry>
                <box size="0.248 0.015 0.06"/>
            </geometry>
        </collision>
        <collision>
            <origin xyz="0 0 0" rpy="1.57079632 0 0"/>
            <geometry>
                <cylinder length="0.018" radius="0.03"/>
            </geometry> 
        </collision>
    </link>
    <joint name="knee_r_joint" type="revolute">
        <origin xyz="0.210 -0.0165 0" rpy="0 3.1416 0"/>
        <parent link="hip_r_link"/>
        <child link="knee_r_link"/>
        <axis xyz="0 1 0"/>
        <limit lower="0.416" upper="2.153" effort="80" velocity="20"/>
    </joint>
    <link name="wheel_r">
        <inertial>
            <origin xyz="0 0 0" rpy="0 0 0"/>
            <mass value="0.468"/>
            <inertia ixx="0.00034258" ixy="0.0" ixz="0.0" iyy="0.00001" iyz="0.0" izz="0.000343769"/>
        </inertial>
        <visual>
            <origin xyz="0 0 0" rpy="0 0 0"/>
            <geometry>
                <mesh filename="../meshes/wheel_r.STL"/>
            </geometry>
            <material name="">
                <color rgba="0.05 0.05 0.05 1"/>
            </material>
        </visual>
        <collision>
            <origin xyz="0 0 0" rpy="1.57079632 0 0"/>
            <geometry>
                <cylinder length="0.015" radius="0.06"/>
            </geometry>
        </collision>
    </link>
    <joint name="wheel_r_joint" type="revolute">
        <origin xyz="0.248 -0.0295 0" rpy="0 0 0"/>
        <parent link="knee_r_link"/>
        <child link="wheel_r"/>
        <axis xyz="0 1 0"/>
        <limit effort="100" velocity="60"/>
    </joint>

</robot>